<?xml version="1.0" ?>
<robot name="bot" xmlns:xacro="http://www.ros.org/wiki/xacro">

<xacro:include filename="$(find bot_description)/urdf/materials.xacro" />
<xacro:include filename="$(find bot_description)/urdf/bot.trans" />
<xacro:include filename="$(find bot_description)/urdf/bot.gazebo" />

<link name="base_link">
  <inertial>
    <origin rpy="0 0 0" xyz="0.4588235848773419 0.1475563890225032 0.4305536898213792"/>
    <mass value="1"/>
    <inertia ixx="0.000843" ixy="-0.0" ixz="-0.0" iyy="0.002626" iyz="-1.6e-05" izz="0.002087"/>
  </inertial>
  <visual>
    <origin rpy="0 0 0" xyz="0 0 0"/>
    <geometry>
      <mesh filename="package://bot_description/meshes/base_link.stl" scale="0.001 0.001 0.001"/>
    </geometry>
    <material name="silver_default"/>
  </visual>
  <collision>
    <origin rpy="0 0 0" xyz="0 0 0"/>
    <geometry>
      <mesh filename="package://bot_description/meshes/base_link.stl" scale="0.001 0.001 0.001"/>
    </geometry>
  </collision>
</link>

<link name="left_foot_1">
  <inertial>
    <origin rpy="0 0 0" xyz="-0.02304248360485034 -2.2504051277461024e-06 -0.05416915490409829"/>
    <mass value="0.25"/>
    <inertia ixx="0.000436" ixy="0.0" ixz="2.6e-05" iyy="0.000444" iyz="-0.0" izz="8e-06"/>
  </inertial>
  <visual>
    <origin rpy="0 0 0" xyz="-0.337324 -0.147203 -0.440063"/>
    <geometry>
      <mesh filename="package://bot_description/meshes/left_foot_1.stl" scale="0.001 0.001 0.001"/>
    </geometry>
    <material name="silver_default"/>
  </visual>
  <collision>
    <origin rpy="0 0 0" xyz="-0.337324 -0.147203 -0.440063"/>
    <geometry>
      <mesh filename="package://bot_description/meshes/left_foot_1.stl" scale="0.001 0.001 0.001"/>
    </geometry>
  </collision>
</link>

<link name="right_foot_1">
  <inertial>
    <origin rpy="0 0 0" xyz="0.02304180933164246 -2.2504051263028124e-06 -0.05416915490391633"/>
    <mass value="0.25"/>
    <inertia ixx="0.000436" ixy="-0.0" ixz="-2.6e-05" iyy="0.000444" iyz="-0.0" izz="8e-06"/>
  </inertial>
  <visual>
    <origin rpy="0 0 0" xyz="-0.580324 -0.147203 -0.440063"/>
    <geometry>
      <mesh filename="package://bot_description/meshes/right_foot_1.stl" scale="0.001 0.001 0.001"/>
    </geometry>
    <material name="silver_default"/>
  </visual>
  <collision>
    <origin rpy="0 0 0" xyz="-0.580324 -0.147203 -0.440063"/>
    <geometry>
      <mesh filename="package://bot_description/meshes/right_foot_1.stl" scale="0.001 0.001 0.001"/>
    </geometry>
  </collision>
</link>

<link name="right_hip_1">
  <inertial>
    <origin rpy="0 0 0" xyz="0.03683398034442853 6.65445204434123e-06 -0.09801652534820487"/>
    <mass value="0.3"/>
    <inertia ixx="0.000498" ixy="0.0" ixz="9.3e-05" iyy="0.000527" iyz="-0.0" izz="4.7e-05"/>
  </inertial>
  <visual>
    <origin rpy="0 0 0" xyz="-0.557324 -0.147203 -0.446863"/>
    <geometry>
      <mesh filename="package://bot_description/meshes/right_hip_1.stl" scale="0.001 0.001 0.001"/>
    </geometry>
    <material name="silver_default"/>
  </visual>
  <collision>
    <origin rpy="0 0 0" xyz="-0.557324 -0.147203 -0.446863"/>
    <geometry>
      <mesh filename="package://bot_description/meshes/right_hip_1.stl" scale="0.001 0.001 0.001"/>
    </geometry>
  </collision>
</link>

<link name="left_hip_1">
  <inertial>
    <origin rpy="0 0 0" xyz="-0.03683526559391298 6.67699216827522e-06 -0.09801612191420034"/>
    <mass value="0.3"/>
    <inertia ixx="0.000498" ixy="-0.0" ixz="-9.3e-05" iyy="0.000527" iyz="-0.0" izz="4.7e-05"/>
  </inertial>
  <visual>
    <origin rpy="0 0 0" xyz="-0.360324 -0.147203 -0.446863"/>
    <geometry>
      <mesh filename="package://bot_description/meshes/left_hip_1.stl" scale="0.001 0.001 0.001"/>
    </geometry>
    <material name="silver_default"/>
  </visual>
  <collision>
    <origin rpy="0 0 0" xyz="-0.360324 -0.147203 -0.446863"/>
    <geometry>
      <mesh filename="package://bot_description/meshes/left_hip_1.stl" scale="0.001 0.001 0.001"/>
    </geometry>
  </collision>
</link>

<!-- Joints -->
<joint name="RevR" type="revolute">
    <origin rpy="0 0 0" xyz="0.557324 0.147203 0.446863"/>
    <parent link="base_link"/>
    <child link="right_hip_1"/>
    <axis xyz="1.0 0.0 0.0"/>
    <limit effort="300" lower="-3.14159" upper="3.14159" velocity="100"/>
</joint>

<joint name="RevL" type="revolute">
    <origin rpy="0 0 0" xyz="0.360324 0.147203 0.446863"/>
    <parent link="base_link"/>
    <child link="left_hip_1"/>
    <axis xyz="1.0 0.0 0.0"/>
    <limit effort="300" lower="-3.14159" upper="3.14159" velocity="100"/>
</joint>

<joint name="SliderR" type="prismatic">
    <origin rpy="0 0 0" xyz="0.023 0.0 -0.0068"/>
    <parent link="right_hip_1"/>
    <child link="right_foot_1"/>
    <axis xyz="0.0 0.0 -1.0"/>
    <limit effort="300" lower="0" upper="0.125" velocity="500"/>
    <dynamics damping="50"/>
</joint>

<joint name="SliderL" type="prismatic">
    <origin rpy="0 0 0" xyz="-0.023 0.0 -0.0068"/>
    <parent link="left_hip_1"/>
    <child link="left_foot_1"/>
    <axis xyz="0.0 0.0 -1.0"/>
    <limit effort="300" lower="0" upper="0.125" velocity="500"/>
    <dynamics damping="50"/>
</joint>

<!-- Links to constrain to planar -->
<link name="world"/>

<link name="y_axis_link">
    <collision>
        <origin xyz="0 0 1" rpy="0 0 0"/>
        <geometry>
            <box size="0.01 0.01 0.01"/>
        </geometry>
    </collision>
    <visual>
        <origin xyz="0 0 1" rpy="0 0 0"/>
        <geometry>
            <box size="0.01 0.01 0.01"/>
        </geometry>
        <material name="silver"/>
    </visual>
    <inertial>
        <origin xyz="0 0 1" rpy="0 0 0"/>
        <mass value="0.01"/>
        <inertia ixx="0.1" ixy="0.0" ixz="0.0" iyy="0.1" iyz="0.0" izz="0.1"/>
    </inertial>
</link>

<joint name="y_direction" type="prismatic">
    <parent link="world"/>
    <child link="y_axis_link"/>
    <axis xyz="0 1 0"/>
    <limit effort="100" lower="-1.79769e+308" upper="1.79769e+308" velocity="100"/>
</joint>

<joint name="z_direction" type="prismatic">
    <parent link="y_axis_link"/>
    <child link="base_link"/>
    <axis xyz="0 0 1"/>
    <limit effort="100" lower="-1.79769e+308" upper="1.79769e+308" velocity="100"/>
</joint>

</robot>
