<robot name="biped">
    
    <gazebo>
        <plugin name="gazebo_ros_control" filename="libgazebo_ros_control.so">
            <robotNamespace>/biped</robotNamespace>
        </plugin>
    </gazebo>

    <gazebo>
        <plugin name="p3d_base_controller" filename="libgazebo_ros_p3d.so">
            <alwaysOn>true</alwaysOn>
            <!--<updateRate>50.0</updateRate>-->
            <bodyName>base</bodyName>
            <topicName>odom</topicName>
            <gaussianNoise>0.01</gaussianNoise>
            <frameName>world</frameName>
            <xyzOffsets>0 0 0</xyzOffsets>
            <rpyOffsets>0 0 0</rpyOffsets>
        </plugin>
    </gazebo>     
    
    <link name="base">
      <inertial>
        <origin xyz="0 0 0" rpy="0 0 0"/>
        <mass value="0.4672" />
        <inertia ixx="0.00506133333333" ixy="0.0" ixz="0.0" iyy="0.00506133333333" iyz="0.0" izz="0.00293333333333"/>
      </inertial>  
      <collision>
        <origin xyz="0 0 0" rpy="0 0 0"/>
        <geometry>
          <box size="0.30 0.30 0.30"/>
        </geometry>
      </collision>  
	    <visual>
	      <geometry>
	        <box size="0.30 0.30 0.30"/>
	      </geometry>
	      <material name="gray">
	        <color rgba="0.3 0.3 0.3 1.0"/>
	      </material>
	    </visual>        
    </link>

    <gazebo reference="base">
      <kp>1000.0</kp>
      <kd>1000.0</kd>
      <mu1>0.5</mu1>
      <mu2>0.5</mu2>
      <material>Gazebo/Gray</material>
    </gazebo>    
    
    <!-- LEFT LEG -->
    <link name="L_hipassembly">
        <inertial>
            <origin xyz="0 0 0" rpy="0 0 0"/>
            <mass value="0.1168" />
            <inertia ixx="0.00140906974933" ixy="0.0" ixz="0.0" iyy="0.001529597616" iyz="0.0" izz="0.000218659333333"/>
        </inertial>
        <collision>
            <origin rpy="0.0 0.0 0.0" xyz="0.0 0.0 0.0"/>
	      <geometry>
	        <mesh filename="package://my_legged_robots_description/meshes/leg/hipassembly.dae" scale="1 1 1"/>
	      </geometry>
        </collision>
	    <visual>
	      <origin rpy="0.0 0.0 0.0" xyz="0.0 0.0 0.0"/>
	      <geometry>
	        <mesh filename="package://my_legged_robots_description/meshes/leg/hipassembly.dae" scale="1 1 1"/>
	      </geometry>
	      <material name="white"/>
	    </visual>
    </link>
    
    <gazebo reference="L_hipassembly">
        <kp>1000.0</kp>
        <kd>1000.0</kd>
        <mu1>0.5</mu1>
        <mu2>0.5</mu2>
        <!--<material>Gazebo/Blue</material>-->
    </gazebo>

    <link name="L_upperleg">
        <inertial>
            <origin xyz="0 0 0" rpy="0 0 0"/>
            <mass value="0.1168" />
            <inertia ixx="0.000119502849333" ixy="0.0" ixz="0.0" iyy="0.00158478921733" iyz="0.0" izz="0.00158585686667"/>
        </inertial>
        <collision>
            <origin rpy="0.0 0.0 0.0" xyz="0.0 0.0 0.0"/>
	      <geometry>
	        <mesh filename="package://my_legged_robots_description/meshes/leg/upperleg.dae" scale="1 1 1"/>
	      </geometry>
        </collision>
	    <visual>
	      <origin rpy="0.0 0.0 0.0" xyz="0.0 0.0 0.0"/>
	      <geometry>
	        <mesh filename="package://my_legged_robots_description/meshes/leg/upperleg.dae" scale="1 1 1"/>
	      </geometry>
	      <material name="blue"/>
	    </visual>
    </link>

    <gazebo reference="L_upperleg">
        <kp>1000.0</kp>
        <kd>1000.0</kd>
        <mu1>0.5</mu1>
        <mu2>0.5</mu2>
        <!--<material>Gazebo/Blue</material>-->
    </gazebo>    
    
    <link name="L_lowerleg">
        <inertial>
            <origin xyz="0 0 0" rpy="0 0 0"/>
            <mass value="0.0292" />
            <inertia ixx="1.74153666667e-05" ixy="0.0" ixz="0.0" iyy="0.000370889177667" iyz="0.0" izz="0.000363771677667"/>
        </inertial>
        <collision>
            <origin rpy="0.0 0.0 0.0" xyz="0.0 0.0 0.0"/>
	      <geometry>
	        <mesh filename="package://my_legged_robots_description/meshes/leg/lowerleg.dae" scale="1 1 1"/>
	      </geometry>
        </collision>
	    <visual>
	      <geometry>
	        <mesh filename="package://my_legged_robots_description/meshes/leg/lowerleg.dae" scale="1 1 1"/>
	      </geometry>
	      <material name="blue"/>
	    </visual>
    </link>
    
    <gazebo reference="L_lowerleg">
        <kp>1000.0</kp>
        <kd>1000.0</kd>
        <mu1>0.5</mu1>
        <mu2>0.5</mu2>
        <!--<material>Gazebo/Blue</material>-->
    </gazebo>


    <joint name="L_haa_joint" type="revolute">
        <origin xyz="0.00000 0.1 -0.15000" rpy="2.0344439357957036 1.5707962290814481 -1.1071487177940917"/>
        <parent link="base"/>
        <child  link="L_hipassembly"/>
        <limit effort="200" lower="-1.6" upper="1.6" velocity="20.0"/>
        <axis xyz="0 0 1"/>
    </joint>
    <joint name="L_hfe_joint" type="revolute">
        <origin xyz="0.08000 0.00000 0.00000" rpy="1.5707963705062866 -0.0 0.0"/>
        <parent link="L_hipassembly"/>
        <child  link="L_upperleg"/>
        <limit effort="200" lower="-1.6" upper="1.6" velocity="20.0"/>
        <axis xyz="0 0 1"/>
    </joint>
    <joint name="L_kfe_joint" type="revolute">
        <origin xyz="0.35000 0.00000 0.00000" rpy="0.0 0.0 0.0"/>
        <parent link="L_upperleg"/>
        <child  link="L_lowerleg"/>
        <limit effort="200" lower="-1.6" upper="1.6" velocity="20.0"/>
        <axis xyz="0 0 1"/>
    </joint>
    
    
    
    <!-- RIGHT LEG -->
    <link name="R_hipassembly">
        <inertial>
            <origin xyz="0 0 0" rpy="0 0 0"/>
            <mass value="0.1168" />
            <inertia ixx="0.00140906974933" ixy="0.0" ixz="0.0" iyy="0.001529597616" iyz="0.0" izz="0.000218659333333"/>
        </inertial>
        <collision>
            <origin rpy="0.0 0.0 0.0" xyz="0.0 0.0 0.0"/>
	      <geometry>
	        <mesh filename="package://my_legged_robots_description/meshes/leg/hipassembly.dae" scale="1 1 1"/>
	      </geometry>
        </collision>
	    <visual>
	      <origin rpy="0.0 0.0 0.0" xyz="0.0 0.0 0.0"/>
	      <geometry>
	        <mesh filename="package://my_legged_robots_description/meshes/leg/hipassembly.dae" scale="1 1 1"/>
	      </geometry>
	      <material name="white"/>
	    </visual>
    </link>

    <gazebo reference="R_hipassembly">
        <kp>1000.0</kp>
        <kd>1000.0</kd>
        <mu1>0.5</mu1>
        <mu2>0.5</mu2>
        <!--<material>Gazebo/Blue</material>-->
    </gazebo>    
    
    <link name="R_upperleg">
        <inertial>
            <origin xyz="0 0 0" rpy="0 0 0"/>
            <mass value="0.1168" />
            <inertia ixx="0.000119502849333" ixy="0.0" ixz="0.0" iyy="0.00158478921733" iyz="0.0" izz="0.00158585686667"/>
        </inertial>
        <collision>
            <origin rpy="0.0 0.0 0.0" xyz="0.0 0.0 0.0"/>
	      <geometry>
	        <mesh filename="package://my_legged_robots_description/meshes/leg/upperleg.dae" scale="1 1 1"/>
	      </geometry>
        </collision>
	    <visual>
	      <origin rpy="0.0 0.0 0.0" xyz="0.0 0.0 0.0"/>
	      <geometry>
	        <mesh filename="package://my_legged_robots_description/meshes/leg/upperleg.dae" scale="1 1 1"/>
	      </geometry>
	      <material name="blue"/>
	    </visual>
    </link>

    <gazebo reference="R_upperleg">
        <kp>1000.0</kp>
        <kd>1000.0</kd>
        <mu1>0.5</mu1>
        <mu2>0.5</mu2>
        <!--<material>Gazebo/Blue</material>-->
    </gazebo>

    <link name="R_lowerleg">
        <inertial>
            <origin xyz="0 0 0" rpy="0 0 0"/>
            <mass value="0.0292" />
            <inertia ixx="1.74153666667e-05" ixy="0.0" ixz="0.0" iyy="0.000370889177667" iyz="0.0" izz="0.000363771677667"/>
        </inertial>
        <collision>
            <origin rpy="0.0 0.0 0.0" xyz="0.0 0.0 0.0"/>
	      <geometry>
	        <mesh filename="package://my_legged_robots_description/meshes/leg/lowerleg.dae" scale="1 1 1"/>
	      </geometry>
        </collision>
	    <visual>
	      <geometry>
	        <mesh filename="package://my_legged_robots_description/meshes/leg/lowerleg.dae" scale="1 1 1"/>
	      </geometry>
	      <material name="blue"/>
	    </visual>
    </link>

    <gazebo reference="R_lowerleg">
        <kp>1000.0</kp>
        <kd>1000.0</kd>
        <mu1>0.5</mu1>
        <mu2>0.5</mu2>
        <!--<material>Gazebo/Blue</material>-->
    </gazebo>
    
    <joint name="R_haa_joint" type="revolute">
        <origin xyz="0.00000 -0.1 -0.15000" rpy="2.0344439357957036 1.5707962290814481 -1.1071487177940917"/>
        <parent link="base"/>
        <child  link="R_hipassembly"/>
        <limit effort="200" lower="-1.6" upper="1.6" velocity="20.0"/>
        <axis xyz="0 0 1"/>
    </joint>
    <joint name="R_hfe_joint" type="revolute">
        <origin xyz="0.08000 0.00000 0.00000" rpy="1.5707963705062866 -0.0 0.0"/>
        <parent link="R_hipassembly"/>
        <child  link="R_upperleg"/>
        <limit effort="200" lower="-1.6" upper="1.6" velocity="20.0"/>
        <axis xyz="0 0 1"/>
    </joint>
    <joint name="R_kfe_joint" type="revolute">
        <origin xyz="0.35000 0.00000 0.00000" rpy="0.0 0.0 0.0"/>
        <parent link="R_upperleg"/>
        <child  link="R_lowerleg"/>
        <limit effort="200" lower="-1.6" upper="1.6" velocity="20.0"/>
        <axis xyz="0 0 1"/>
    </joint>

    <!-- Transmission -->>  
    <transmission name="L_haa_joint_trans">
      <type>transmission_interface/SimpleTransmission</type>
      <joint name="L_haa_joint">
        <hardwareInterface>hardware_interface/EffortJointInterface</hardwareInterface>
      </joint>
      <actuator name="L_haa_jointMotor">
        <hardwareInterface>hardware_interface/EffortJointInterface</hardwareInterface>
        <mechanicalReduction>1</mechanicalReduction>
      </actuator>
    </transmission>

    <transmission name="L_hfe_joint_trans">
      <type>transmission_interface/SimpleTransmission</type>
      <joint name="L_hfe_joint">
        <hardwareInterface>hardware_interface/EffortJointInterface</hardwareInterface>
      </joint>
      <actuator name="L_hfe_jointMotor">
        <hardwareInterface>hardware_interface/EffortJointInterface</hardwareInterface>
        <mechanicalReduction>1</mechanicalReduction>
      </actuator>
    </transmission>

    <transmission name="L_kfe_joint_trans">
      <type>transmission_interface/SimpleTransmission</type>
      <joint name="L_kfe_joint">
        <hardwareInterface>hardware_interface/EffortJointInterface</hardwareInterface>
      </joint>
      <actuator name="L_kfe_jointMotor">
        <hardwareInterface>hardware_interface/EffortJointInterface</hardwareInterface>
        <mechanicalReduction>1</mechanicalReduction>
      </actuator>
    </transmission>

    <transmission name="R_haa_joint_trans">
      <type>transmission_interface/SimpleTransmission</type>
      <joint name="R_haa_joint">
        <hardwareInterface>hardware_interface/EffortJointInterface</hardwareInterface>
      </joint>
      <actuator name="R_haa_jointMotor">
        <hardwareInterface>hardware_interface/EffortJointInterface</hardwareInterface>
        <mechanicalReduction>1</mechanicalReduction>
      </actuator>
    </transmission>

    <transmission name="R_hfe_joint_trans">
      <type>transmission_interface/SimpleTransmission</type>
      <joint name="R_hfe_joint">
        <hardwareInterface>hardware_interface/EffortJointInterface</hardwareInterface>
      </joint>
      <actuator name="R_hfe_jointMotor">
        <hardwareInterface>hardware_interface/EffortJointInterface</hardwareInterface>
        <mechanicalReduction>1</mechanicalReduction>
      </actuator>
    </transmission>

    <transmission name="R_kfe_joint_trans">
      <type>transmission_interface/SimpleTransmission</type>
      <joint name="R_kfe_joint">
        <hardwareInterface>hardware_interface/EffortJointInterface</hardwareInterface>
      </joint>
      <actuator name="R_kfe_jointMotor">
        <hardwareInterface>hardware_interface/EffortJointInterface</hardwareInterface>
        <mechanicalReduction>1</mechanicalReduction>
      </actuator>
    </transmission>    

</robot>

